Workbook

Sheet Back Data Lenvean Pit Lake
A1: Leveaniemi Pit Lake Water Quality (SWECO, 2007 & MKB2012)
C3: Leveaniemi | G3: Gruvberget | H3: Leveaniemi | J3: SVA63 | K3: Mettresk | L3: Resipient | O3: LIUKATTIJOKI | P3: LUUKAJOKI
C4: SVA49&50 | H4: GW | K4: SVA57 | L4: SVA58 | O4: SVA24 | P4: SVA13
A5: pH | C5: 7.9 | K5: 7.8 | L5: 8 | O5: 7.3 | P5: 7.1
A6: Alk | B6: mmol/l | C6: 2.3 | G6: 1.5 | H6: 2.0771429 | K6: 0.93 | L6: 0.84 | O6: 0.39 | P6: 0.41
A7: Kond. | B7: mS/l | C7: 41.8 | O7: 47 | P7: 5.2
A8: Cl | B8: mg/l | C8: 12 | G8: 8.2 | H8: 1.88 | J8: <0.10 | K8: 170 | L8: 195
A9: F | C9: 0.15 | G9: 0.17 | H9: 0.10142857 | J9: <0.10 | K9: 1.1 | L9: 1.3
A10: SO4 | B10: mg/l | C10: 68.7 | G10: 18.8 | H10: 125.84286 | J10: 1 | K10: 461 | L10: 521
A11: P-tot | B11: mg/l | C11: <0.005 | G11: 0.08 | H11: 0.030285714 | J11: 0.02 | O11: <0.007 | P11: <0.007
A12: N-tot | B12: mg/l | C12: 1.4 | G12: 11.9 | H12: 0.1255 | J12: 0.27 | K12: 8.4 | L12: 9.5 | O12: 0.92 | P12: 0.2
A13: NO3-N | B13: mg/l | C13: 0.12 | G13: 7.4 | H13: <0.23 | J13: <0.23 | K13: 7.5 | L13: 9.7 | M13: =K14/K13 -> 0.014666667 | N13: =L14/L13 -> 0.0091752577 | O13: 0.72 | P13: <0.23
A14: NH4-N | B14: mg/l | C14: <0.011 | G14: 3.33 | H14: 0.09 | J14: <0,010 | K14: 0.11 | L14: 0.089 | O14: <0.01 | P14: <0.01
A15: Ca | B15: mg/l | C15: 58.4 | G15: 35.5 | H15: 68.228571 | J15: 1.6 | K15: 174 | L15: 191
A16: As | B16: ug/l | C16: <0.055 | G16: ND | H16: 0.11575714 | J16: 0.07 | K16: 0.34 | L16: 0.59 | O16: <0.08 | P16: <0.1
A17: Ba | B17: ug/l | C17: 11.3 | G17: 17.7 | H17: 30.228571 | J17: 5.64 | K17: 37 | L17: 35.2 | O17: 12.8 | P17: 8.6
A18: Cd | B18: ug/l | C18: 0.001 | G18: 0.0033 | H18: 0.0051571429 | J18: <0.004 | K18: 0.001 | L18: 0.001 | O18: <0.004 | P18: <0.002
A19: Co | B19: ug/l | C19: 0.27 | G19: 0.34 | H19: 0.13457143 | J19: 0.14 | K19: 0.272 | L19: 0.291 | O19: 0.1 | P19: 0.06
A20: Cr | B20: ug/l | C20: 0.003 | G20: 0.04 | H20: 0.33601429 | J20: 0.26 | K20: 0.0506 | L20: 0.0495 | O20: 1 | P20: 0.31
A21: Cu | B21: ug/l | C21: 8.8 | G21: 4.4 | H21: 0.18128571 | J21: 0.51 | K21: 2.07 | L21: 2.17 | O21: 0.23 | P21: 0.13
A22: Hg | B22: ug/l | C22: <0.002 | G22: ND | H22: nd | J22: <0.002 | K22: <0.002 | L22: <0.002 | O22: <0.002 | P22: <0.002
A23: Mo | B23: ug/l | C23: 3.6 | G23: 4.6 | H23: 0.944 | J23: <0.05 | K23: 19.2 | L23: 22.7 | O23: 1 | P23: 0.31
A24: Ni | B24: ug/l | C24: 0.84 | G24: 0.19 | H24: 0.80142857 | J24: 0.41 | K24: 1.07 | L24: 1.07 | O24: 0.23 | P24: 0.13
A25: Pb | B25: ug/l | C25: <0.01 | G25: ND | H25: <0.01 | J25: 0.025 | K25: <0.01 | L25: <0.01 | O25: 0.02 | P25: 0.02
A26: Sr | B26: ug/l | C26: 74 | G26: ND | H26: 167 | J26: na | K26: na | L26: na | O26: 52 | P26: 12.5
A27: V | B27: ug/l | C27: 2.1 | G27: 1.18 | H27: 0.35827143 | J27: 0.2 | K27: 0.47 | L27: 2.57 | O27: 0.08 | P27: 0.07
A28: Zn | B28: ug/l | C28: 1.5 | G28: 1.31 | H28: 2.7977143 | J28: 2.6 | K28: 0.93 | L28: 0.95 | O28: 2.8 | P28: 1
A29: Mg | B29: mg/l | C29: 10.1 | G29: 4.02 | H29: 14.381429 | K29: 21 | L29: 21
A30: Na | B30: mg/l | C30: 7.4 | G30: 9.67 | H30: 10.958571 | K30: 106 | L30: 115
A31: K | B31: mg/l | C31: 7.1 | G31: 3.77 | H31: 10.721429 | K31: 45 | L31: 49
A32: Mn | B32: ug/l | H32: 373.78
A33: Fe | B33: ug/l | H33: 0.0199
K34: 0.013 | L34: <0.002
A35: Waste Rock Leaching data
D36: Leptite | G36: Diabase | J36: Biotiteskifer | L36: Inert Avfall
C37: 0 | D37: 2 | E37: 10 | F37: 0 | G37: 2 | H37: 10 | I37: 0 | J37: 2 | K37: 10 | L37: L/S 2 | M37: L/S10
A38: TS efter siktning | D38: 99.8 | E38: 99.8 | G38: 99.8 | H38: 99.8 | J38: 99.6 | K38: 99.6
A39: Invegning | B39: g | D39: 175.4 | E39: 175.4 | G39: 175.4 | H39: 175.4 | J39: 175.7 | K39: 175.7
A40: Volym efter filtr. L/S2 | B40: ml | D40: 294 | G40: 300 | J40: 298
A41: Volym tilsatt | B41: ml | D41: 350 | E41: 1400 | G41: 350 | H41: 1400 | J41: 349 | K41: 1400
...

Sheet Hist modellering
C2: Lake copper con. | D2: Copper add/year | E2: Lake volume | F2: Lake volume | G2: Yearly addition | H2: Net Rainwater | I2: Ground water contribution | J2: Groundwater | K2: surface leaching | L2: surface area for leaching | M2: Leaching | N2: ground water
A3: # years | B3: ÅR | D3: ug/l | E3: Mm3 | F3: m3 | G3: m3/year | H3: m3/year | I3: kg/year | J3: m3/year | K3: kg/year | L3: m2 | M3: mg/m2/year | N3: ug/l
A4: 29 | B4: 2012 | C4: =(D4*G4+D5*F5)/F4 -> 7.8780934 | D4: =(K4+I4)*1000/G4*1000 -> 7.4379756 | E4: =F4/1000000 -> 31.22064 | F4: =F5+H4+J4 -> 31220640 | G4: =H4+J4 -> 756864 | H4: =6*60*60*24*365/1000 -> 189216 | I4: =J4*1000*$N$4/1000000000 -> 0.567648 | J4: =18*60*60*24*365/1000 -> 567648 | K4: =L4*$M$4/1000000 -> 5.061888 | L4: 281216 | M4: 18 | N4: 1
A5: =A4-1 -> 28 | B5: =B4-1 -> 2011 | C5: =(D5*G5+D6*F6)/F5 -> 8.3069667 | D5: =(K5+I5)*1000/G5*1000 -> 7.889028 | E5: =F5/1000000 -> 30.463776 | F5: =F6+H5+J5 -> 30463776 | G5: =H5+J5 -> 776438.07 | H5: =H4 -> 189216 | I5: =J5*1000*$N$4/1000000000 -> 0.58722207 | J5: =J4+(J$33-J$4)/29 -> 587222.07 | K5: =L5*$M$4/1000000 -> 5.5381196 | L5: =L4+(L$33-L$4)/29 -> 307673.31
A6: =A5-1 -> 27 | B6: =B5-1 -> 2010 | C6: =(D6*G6+D7*F7)/F6 -> 8.7152337 | D6: =(K6+I6)*1000/G6*1000 -> 8.3178974 | E6: =F6/1000000 -> 29.687338 | F6: =F7+H6+J6 -> 29687338 | G6: =H6+J6 -> 796012.14 | H6: =H5 -> 189216 | I6: =J6*1000*$N$4/1000000000 -> 0.60679614 | J6: =J5+(J$33-J$4)/29 -> 606796.14 | K6: =L6*$M$4/1000000 -> 6.0143512 | L6: =L5+(L$33-L$4)/29 -> 334130.62
A7: =A6-1 -> 26 | B7: =B6-1 -> 2009 | C7: =(D7*G7+D8*F8)/F7 -> 9.1043412 | D7: =(K7+I7)*1000/G7*1000 -> 8.7261811 | E7: =F7/1000000 -> 28.891326 | F7: =F8+H7+J7 -> 28891326 | G7: =H7+J7 -> 815586.21 | H7: =H6 -> 189216 | I7: =J7*1000*$N$4/1000000000 -> 0.62637021 | J7: =J6+(J$33-J$4)/29 -> 626370.21 | K7: =L7*$M$4/1000000 -> 6.4905828 | L7: =L6+(L$33-L$4)/29 -> 360587.93
A8: =A7-1 -> 25 | B8: =B7-1 -> 2008 | C8: =(D8*G8+D9*F9)/F8 -> 9.4756029 | D8: =(K8+I8)*1000/G8*1000 -> 9.1153265 | E8: =F8/1000000 -> 28.07574 | F8: =F9+H8+J8 -> 28075740 | G8: =H8+J8 -> 835160.28 | H8: =H7 -> 189216 | I8: =J8*1000*$N$4/1000000000 -> 0.64594428 | J8: =J7+(J$33-J$4)/29 -> 645944.28 | K8: =L8*$M$4/1000000 -> 6.9668143 | L8: =L7+(L$33-L$4)/29 -> 387045.24
A9: =A8-1 -> 24 | B9: =B8-1 -> 2007 | C9: =(D9*G9+D10*F10)/F9 -> 9.8302147 | D9: =(K9+I9)*1000/G9*1000 -> 9.4866485 | E9: =F9/1000000 -> 27.240579 | F9: =F10+H9+J9 -> 27240579 | G9: =H9+J9 -> 854734.34 | H9: =H8 -> 189216 | I9: =J9*1000*$N$4/1000000000 -> 0.66551834 | J9: =J8+(J$33-J$4)/29 -> 665518.34 | K9: =L9*$M$4/1000000 -> 7.4430459 | L9: =L8+(L$33-L$4)/29 -> 413502.55
A10: =A9-1 -> 23 | B10: =B9-1 -> 2006 | C10: =(D10*G10+D11*F11)/F10 -> 10.169267 | D10: =(K10+I10)*1000/G10*1000 -> 9.8413441 | E10: =F10/1000000 -> 26.385845 | F10: =F11+H10+J10 -> 26385845 | G10: =H10+J10 -> 874308.41 | H10: =H9 -> 189216 | I10: =J10*1000*$N$4/1000000000 -> 0.68509241 | J10: =J9+(J$33-J$4)/29 -> 685092.41 | K10: =L10*$M$4/1000000 -> 7.9192775 | L10: =L9+(L$33-L$4)/29 -> 439959.86
A11: =A10-1 -> 22 | B11: =B10-1 -> 2005 | C11: =(D11*G11+D12*F12)/F11 -> 10.493757 | D11: =(K11+I11)*1000/G11*1000 -> 10.180506 | E11: =F11/1000000 -> 25.511537 | F11: =F12+H11+J11 -> 25511537 | G11: =H11+J11 -> 893882.48 | H11: =H10 -> 189216 | I11: =J11*1000*$N$4/1000000000 -> 0.70466648 | J11: =J10+(J$33-J$4)/29 -> 704666.48 | K11: =L11*$M$4/1000000 -> 8.3955091 | L11: =L10+(L$33-L$4)/29 -> 466417.17
A12: =A11-1 -> 21 | B12: =B11-1 -> 2004 | C12: =(D12*G12+D13*F13)/F12 -> 10.804597 | D12: =(K12+I12)*1000/G12*1000 -> 10.505132 | E12: =F12/1000000 -> 24.617654 | F12: =F13+H12+J12 -> 24617654 | G12: =H12+J12 -> 913456.55 | H12: =H11 -> 189216 | I12: =J12*1000*$N$4/1000000000 -> 0.72424055 | J12: =J11+(J$33-J$4)/29 -> 724240.55 | K12: =L12*$M$4/1000000 -> 8.8717407 | L12: =L11+(L$33-L$4)/29 -> 492874.48
A13: =A12-1 -> 20 | B13: =B12-1 -> 2003 | C13: =(D13*G13+D14*F14)/F13 -> 11.102623 | D13: =(K13+I13)*1000/G13*1000 -> 10.816137 | E13: =F13/1000000 -> 23.704198 | F13: =F14+H13+J13 -> 23704198 | G13: =H13+J13 -> 933030.62 | H13: =H12 -> 189216 | I13: =J13*1000*$N$4/1000000000 -> 0.74381462 | J13: =J12+(J$33-J$4)/29 -> 743814.62 | K13: =L13*$M$4/1000000 -> 9.3479723 | L13: =L12+(L$33-L$4)/29 -> 519331.79
A14: =A13-1 -> 19 | B14: =B13-1 -> 2002 | C14: =(D14*G14+D15*F15)/F14 -> 11.388603 | D14: =(K14+I14)*1000/G14*1000 -> 11.114361 | E14: =F14/1000000 -> 22.771167 | F14: =F15+H14+J14 -> 22771167 | G14: =H14+J14 -> 952604.69 | H14: =H13 -> 189216 | I14: =J14*1000*$N$4/1000000000 -> 0.76338869 | J14: =J13+(J$33-J$4)/29 -> 763388.69 | K14: =L14*$M$4/1000000 -> 9.8242039 | L14: =L13+(L$33-L$4)/29 -> 545789.1
A15: =A14-1 -> 18 | B15: =B14-1 -> 2001 | C15: =(D15*G15+D16*F16)/F15 -> 11.663244 | D15: =(K15+I15)*1000/G15*1000 -> 11.400576 | E15: =F15/1000000 -> 21.818562 | F15: =F16+H15+J15 -> 21818562 | G15: =H15+J15 -> 972178.76 | H15: =H14 -> 189216 | I15: =J15*1000*$N$4/1000000000 -> 0.78296276 | J15: =J14+(J$33-J$4)/29 -> 782962.76 | K15: =L15*$M$4/1000000 -> 10.300435 | L15: =L14+(L$33-L$4)/29 -> 572246.41
A16: =A15-1 -> 17 | B16: =B15-1 -> 2000 | C16: =(D16*G16+D17*F17)/F16 -> 11.927196 | D16: =(K16+I16)*1000/G16*1000 -> 11.675494 | E16: =F16/1000000 -> 20.846383 | F16: =F17+H16+J16 -> 20846383 | G16: =H16+J16 -> 991752.83 | H16: =H15 -> 189216 | I16: =J16*1000*$N$4/1000000000 -> 0.80253683 | J16: =J15+(J$33-J$4)/29 -> 802536.83 | K16: =L16*$M$4/1000000 -> 10.776667 | L16: =L15+(L$33-L$4)/29 -> 598703.72
... A30: =A29-1 -> 3 | B30: =B29-1 -> 1986 | C30: =(D30*G30+D31*F31)/F30 -> 14.754673 | D30: =(K30+I30)*1000/G30*1000 -> 14.631563 | E30: =F30/1000000 -> 5.1806036 | F30: =F31+H30+J30 -> 5180603.6 | G30: =H30+J30 -> 1265789.8 | H30: =H29 -> 189216 | I30: =J30*1000*$N$4/1000000000 -> 1.0765738 | J30: =J29+(J$33-J$4)/29 -> 1076573.8 | K30: =L30*$M$4/1000000 -> 17.443909 | L30: =L29+(L$33-L$4)/29 -> 969106.07
A31: =A30-1 -> 2 | B31: =B30-1 -> 1985 | C31: =(D31*G31+D32*F32)/F31 -> 14.900622 | D31: =(K31+I31)*1000/G31*1000 -> 14.794479 | E31: =F31/1000000 -> 3.9148138 | F31: =F32+H31+J31 -> 3914813.8 | G31: =H31+J31 -> 1285363.9 | H31: =H30 -> 189216 | I31: =J31*1000*$N$4/1000000000 -> 1.0961479 | J31: =J30+(J$33-J$4)/29 -> 1096147.9 | K31: =L31*$M$4/1000000 -> 17.920141 | L31: =L30+(L$33-L$4)/29 -> 995563.38 | M31: 2932848 | N31: Grundvatten - bottom nytt Leveniemi, Bergab2012
A32: =A31-1 -> 1 | B32: =B31-1 -> 1984 | C32: =(D32*G32+D33*G33)/F32 -> 15.029757 | D32: =(K32+I32)*1000/G32*1000 -> 14.952508 | E32: =F32/1000000 -> 2.6294499 | F32: =F33+H32+J32 -> 2629449.9 | G32: =H32+J32 -> 1304937.9 | H32: =H31 -> 189216 | I32: =J32*1000*$N$4/1000000000 -> 1.1157219 | J32: =J31+(J$33-J$4)/29 -> 1115721.9 | K32: =L32*$M$4/1000000 -> 18.396372 | L32: =L31+(L$33-L$4)/29 -> 1022020.7 | M32: 388592 | N32: Regnvann SWECO 2012
A33: =A32-1 -> 0 | B33: =B32-1 -> 1983 | C33: =D33 -> 15.105865 | D33: =(K33+I33)*1000000/F33 -> 15.105865 | E33: =F33/1000000 -> 1.324512 | F33: =H33+J33 -> 1324512 | G33: =H33+J33 -> 1324512 | H33: =H32 -> 189216 | I33: =J33*1000*$N$4/1000000000 -> 1.135296 | J33: =M34 -> 1135296 | K33: =L33*$M$4/1000000 -> 18.872604 | L33: 1048478 | M33: =6*60*60*24*365/1000 -> 189216 | N33: Regnvann Miljøbyrån 2010
M34: =36*60*60*24*365/1000 -> 1135296 | N34: Grundvatten 1983 - Miljøbyrån 2010
B35: 2020 | J35: 2932848 | L35: 1129047 | M35: =18*60*60*24*365/1000 -> 567648 | N35: Grundvatten 2010 - Miljøbyrån 2010
L36: 1048478
B37: 2932848
C83: Lake Ni con. | D83: Nickle add/year | E83: Lake volume | F83: Lake volume | G83: Yearly addition | H83: Net Rainwater | I83: Ground water contribution | J83: Groundwater | K83: surface leaching | L83: surface area for leaching | M83: Leaching | N83: ground water | O83: PIT WATER 2007
A84: # years | B84: ÅR | D84: ug/l | E84: Mm3 | F84: m3 | G84: m3/year | H84: m3/year | I84: kg/year | J84: m3/year | K84: kg/year | L84: m2 | M84: mg/m2/year | N84: ug/l
A85: 29 | B85: 2012 | C85: =(D85*G85+D86*F86)/F85 -> 0.83845492 | D85: =(K85+I85)*1000/G85*1000 -> 0.78776383 | E85: =F85/1000000 -> 31.22064 | F85: =F86+H85+J85 -> 31220640 | G85: =H85+J85 -> 756864 | H85: =6*60*60*24*365/1000 -> 189216 | I85: =J85*1000*$N$85/1000000000 -> 0.00567648 | J85: =18*60*60*24*365/1000 -> 567648 | K85: =L85*M$85/1000000 -> 0.5905536 | L85: 281216 | M85: 2.1 | N85: 0.01 | O85: 0.1
A86: =A85-1 -> 28 | B86: =B85-1 -> 2011 | C86: =(D86*G86+D87*F87)/F86 -> 0.88785093 | D86: =(K86+I86)*1000/G86*1000 -> 0.83971433 | E86: =F86/1000000 -> 30.463776 | F86: =F87+H86+J86 -> 30463776 | G86: =H86+J86 -> 776438.07 | H86: =H85 -> 189216 | I86: =J86*1000*$N$85/1000000000 -> 0.0058722207 | J86: =J85+(J$33-J$4)/29 -> 587222.07 | K86: =L86*M$85/1000000 -> 0.64611395 | L86: =L85+(L$33-L$4)/29 -> 307673.31
A87: =A86-1 -> 27 | B87: =B86-1 -> 2010 | C87: =(D87*G87+D88*F88)/F87 -> 0.93487359 | D87: =(K87+I87)*1000/G87*1000 -> 0.88910989 | E87: =F87/1000000 -> 29.687338 | F87: =F88+H87+J87 -> 29687338 | G87: =H87+J87 -> 796012.14 | H87: =H86 -> 189216 | I87: =J87*1000*$N$85/1000000000 -> 0.0060679614 | J87: =J86+(J$33-J$4)/29 -> 606796.14 | K87: =L87*M$85/1000000 -> 0.7016743 | L87: =L86+(L$33-L$4)/29 -> 334130.62
A88: =A87-1 -> 26 | B88: =B87-1 -> 2009 | C88: =(D88*G88+D89*F89)/F88 -> 0.97968951 | D88: =(K88+I88)*1000/G88*1000 -> 0.93613446 | E88: =F88/1000000 -> 28.891326 | F88: =F89+H88+J88 -> 28891326 | G88: =H88+J88 -> 815586.21 | H88: =H87 -> 189216 | I88: =J88*1000*$N$85/1000000000 -> 0.0062637021 | J88: =J87+(J$33-J$4)/29 -> 626370.21 | K88: =L88*M$85/1000000 -> 0.75723466 | L88: =L87+(L$33-L$4)/29 -> 360587.93
A89: =A88-1 -> 25 | B89: =B88-1 -> 2008 | C89: =(D89*G89+D90*F90)/F89 -> 1.02245 | D89: =(K89+I89)*1000/G89*1000 -> 0.98095476 | E89: =F89/1000000 -> 28.07574 | F89: =F90+H89+J89 -> 28075740 | G89: =H89+J89 -> 835160.28 | H89: =H88 -> 189216 | I89: =J89*1000*$N$85/1000000000 -> 0.0064594428 | J89: =J88+(J$33-J$4)/29 -> 645944.28 | K89: =L89*M$85/1000000 -> 0.81279501 | L89: =L88+(L$33-L$4)/29 -> 387045.24
A90: =A89-1 -> 24 | B90: =B89-1 -> 2007 | C90: =(D90*G90+D91*F91)/F90 -> 1.0632929 | D90: =(K90+I90)*1000/G90*1000 -> 1.0237222 | E90: =F90/1000000 -> 27.240579 | F90: =F91+H90+J90 -> 27240579 | G90: =H90+J90 -> 854734.34 | H90: =H89 -> 189216 | I90: =J90*1000*$N$85/1000000000 -> 0.0066551834 | J90: =J89+(J$33-J$4)/29 -> 665518.34 | K90: =L90*M$85/1000000 -> 0.86835536 | L90: =L89+(L$33-L$4)/29 -> 413502.55 | M90: 20 | N90: 68.2 | O90: 58.4 | P90: Ca
A91: =A90-1 -> 23 | B91: =B90-1 -> 2006 | C91: =(D91*G91+D92*F92)/F91 -> 1.1023437 | D91: =(K91+I91)*1000/G91*1000 -> 1.0645747 | E91: =F91/1000000 -> 26.385845 | F91: =F92+H91+J91 -> 26385845 | G91: =H91+J91 -> 874308.41 | H91: =H90 -> 189216 | I91: =J91*1000*$N$85/1000000000 -> 0.0068509241 | J91: =J90+(J$33-J$4)/29 -> 685092.41 | K91: =L91*M$85/1000000 -> 0.92391571 | L91: =L90+(L$33-L$4)/29 -> 439959.86 | M91: 0 | N91: 126 | O91: 68.7 | P91: SO4
A92: =A91-1 -> 22 | B92: =B91-1 -> 2005 | C92: =(D92*G92+D93*F93)/F92 -> 1.1397172 | D92: =(K92+I92)*1000/G92*1000 -> 1.1036381 | E92: =F92/1000000 -> 25.511537 | F92: =F93+H92+J92 -> 25511537 | G92: =H92+J92 -> 893882.48 | H92: =H91 -> 189216 | I92: =J92*1000*$N$85/1000000000 -> 0.0070466648 | J92: =J91+(J$33-J$4)/29 -> 704666.48 | K92: =L92*M$85/1000000 -> 0.97947606 | L92: =L91+(L$33-L$4)/29 -> 466417.17 | M92: 27 | N92: 1.88 | O92: 12 | P92: Cl
A93: =A92-1 -> 21 | B93: =B92-1 -> 2004 | C93: =(D93*G93+D94*F94)/F93 -> 1.1755185 | D93: =(K93+I93)*1000/G93*1000 -> 1.1410273 | E93: =F93/1000000 -> 24.617654 | F93: =F94+H93+J93 -> 24617654 | G93: =H93+J93 -> 913456.55 | H93: =H92 -> 189216 | I93: =J93*1000*$N$85/1000000000 -> 0.0072424055 | J93: =J92+(J$33-J$4)/29 -> 724240.55 | K93: =L93*M$85/1000000 -> 1.0350364 | L93: =L92+(L$33-L$4)/29 -> 492874.48 | M93: 19 | N93: 0.18 | O93: 7.7 | P93: Cu
A94: =A93-1 -> 20 | B94: =B93-1 -> 2003 | C94: =(D94*G94+D95*F95)/F94 -> 1.209844 | D94: =(K94+I94)*1000/G94*1000 -> 1.1768477 | E94: =F94/1000000 -> 23.704198 | F94: =F95+H94+J94 -> 23704198 | G94: =H94+J94 -> 933030.62 | H94: =H93 -> 189216 | I94: =J94*1000*$N$85/1000000000 -> 0.0074381462 | J94: =J93+(J$33-J$4)/29 -> 743814.62 | K94: =L94*M$85/1000000 -> 1.0905968 | L94: =L93+(L$33-L$4)/29 -> 519331.79 | M94: 1.4 | N94: 0.38 | O94: 0.84 | P94: Ni
A95: =A94-1 -> 19 | B95: =B94-1 -> 2002 | C95: =(D95*G95+D96*F96)/F95 -> 1.2427821 | D95: =(K95+I95)*1000/G95*1000 -> 1.211196 | E95: =F95/1000000 -> 22.771167 | F95: =F96+H95+J95 -> 22771167 | G95: =H95+J95 -> 952604.69 | H95: =H94 -> 189216 | I95: =J95*1000*$N$85/1000000000 -> 0.0076338869 | J95: =J94+(J$33-J$4)/29 -> 763388.69 | K95: =L95*M$85/1000000 -> 1.1461571 | L95: =L94+(L$33-L$4)/29 -> 545789.1 | M95: 0.01 | N95: 0.27 | O95: 0.13 | P95: Co
A96: =A95-1 -> 18 | B96: =B95-1 -> 2001 | C96: =(D96*G96+D97*F97)/F96 -> 1.2744143 | D96: =(K96+I96)*1000/G96*1000 -> 1.2441612 | E96: =F96/1000000 -> 21.818562 | F96: =F97+H96+J96 -> 21818562 | G96: =H96+J96 -> 972178.76 | H96: =H95 -> 189216 | I96: =J96*1000*$N$85/1000000000 -> 0.0078296276 | J96: =J95+(J$33-J$4)/29 -> 782962.76 | K96: =L96*M$85/1000000 -> 1.2017175 | L96: =L95+(L$33-L$4)/29 -> 572246.41 | M96: 0.01 | N96: 2.8 | O96: 1.5 | P96: Zn
A97: =A96-1 -> 17 | B97: =B96-1 -> 2000 | C97: =(D97*G97+D98*F98)/F97 -> 1.3048153 | D97: =(K97+I97)*1000/G97*1000 -> 1.2758251 | E97: =F97/1000000 -> 20.846383 | F97: =F98+H97+J97 -> 20846383 | G97: =H97+J97 -> 991752.83 | H97: =H96 -> 189216 | I97: =J97*1000*$N$85/1000000000 -> 0.0080253683 | J97: =J96+(J$33-J$4)/29 -> 802536.83 | K97: =L97*M$85/1000000 -> 1.2572778 | L97: =L96+(L$33-L$4)/29 -> 598703.72 | M97: 7.5 | N97: 0.94 | O97: 3.6 | P97: Mo
A98: =A97-1 -> 16 | B98: =B97-1 -> 1999 | C98: =(D98*G98+D99*F99)/F98 -> 1.3340542 | D98: =(K98+I98)*1000/G98*1000 -> 1.3062634 | E98: =F98/1000000 -> 19.854631 | F98: =F99+H98+J98 -> 19854631 | G98: =H98+J98 -> 1011326.9 | H98: =H97 -> 189216 | I98: =J98*1000*$N$85/1000000000 -> 0.008221109 | J98: =J97+(J$33-J$4)/29 -> 822110.9 | K98: =L98*M$85/1000000 -> 1.3128382 | L98: =L97+(L$33-L$4)/29 -> 625161.03 | M98: 0.2 | N98: 0.02 | O98: 0.005 | P98: Po4-P
A99: =A98-1 -> 15 | B99: =B98-1 -> 1998 | C99: =(D99*G99+D100*F100)/F99 -> 1.3621945 | D99: =(K99+I99)*1000/G99*1000 -> 1.3355457 | E99: =F99/1000000 -> 18.843304 | F99: =F100+H99+J99 -> 18843304 | G99: =H99+J99 -> 1030901 | H99: =H98 -> 189216 | I99: =J99*1000*$N$85/1000000000 -> 0.0084168497 | J99: =J98+(J$33-J$4)/29 -> 841684.97 | K99: =L99*M$85/1000000 -> 1.3683985 | L99: =L98+(L$33-L$4)/29 -> 651618.34 | N99: 0.11 | O99: <0.055 | P99: As
...

Sheet Modell During mining
A1: Leveaniemi pit water drainge prediction
C2: Lake copper con. | D2: Mean summer Copper conc./year | E2: Lake volume | F2: Lake volume | G2: Yearly discharge | H2: Net Rainwater | I2: Ground water contribution | J2: Groundwater | K2: surface leaching | L2: surface area for leaching | M2: Leaching | N2: ground water
A3: # years | B3: ÅR | D3: ug/l | E3: Mm3 | F3: m3 | G3: m3/year | H3: m3/year | I3: kg/year | J3: m3/year | K3: kg/year | L3: m2 | M3: mg/m2/year | N3: ug/l
A4: 0 | B4: 2014 | C4: =(D4*G4+D5*F5)/F4 -> 21.578451 | D4: =(K4*1000/G4*12/7*1000)+(I4/G4*7/12*1000) -> 24.426882 | E4: =F4/1000000 -> 43.842048 | F4: =F5+H4+J4 -> 43842048 | G4: =H4+J4 -> 1324512 | H4: =6*60*60*24*365/1000 -> 189216 | I4: =J4*1000*$N$4/1000000000 -> 1.135296 | J4: =36*60*60*24*365/1000 -> 1135296 | K4: =L4*$M$4/1000000 -> 18.872604 | L4: 1048478 | M4: 18 | N4: 1
A5: =A4+1 -> 1 | B5: =B4+1 -> 2015 | C5: =(D5*G5+D6*F6)/F5 -> 19.285353 | D5: =(K5*1000/G5*12/7*1000)+(I5/G5*7/12*1000) -> 21.489717 | E5: =F5/1000000 -> 42.517536 | F5: =F6+H5+J5 -> 42517536 | G5: =H5+J5 -> 1513260.8 | H5: =H4+(H$19-H$4)/15 -> 195523.2 | I5: =J5*1000*$N$4/1000000000 -> 1.3177376 | J5: =J4+(J$19-J$4)/15 -> 1317737.6 | K5: =L5*$M$4/1000000 -> 18.969287 | L5: =L4+(L$19-L$4)/15 -> 1053849.3
A6: =A5+1 -> 2 | B6: =B5+1 -> 2016 | C6: =(D6*G6+D7*F7)/F6 -> 17.450571 | D6: =(K6*1000/G6*12/7*1000)+(I6/G6*7/12*1000) -> 19.204001 | E6: =F6/1000000 -> 41.004275 | F6: =F7+H6+J6 -> 41004275 | G6: =H6+J6 -> 1702009.6 | H6: =H5+(H$19-H$4)/15 -> 201830.4 | I6: =J6*1000*$N$4/1000000000 -> 1.5001792 | J6: =J5+(J$19-J$4)/15 -> 1500179.2 | K6: =L6*$M$4/1000000 -> 19.06597 | L6: =L5+(L$19-L$4)/15 -> 1059220.5
A7: =A6+1 -> 3 | B7: =B6+1 -> 2017 | C7: =(D7*G7+D8*F8)/F7 -> 15.949394 | D7: =(K7*1000/G7*12/7*1000)+(I7/G7*7/12*1000) -> 17.374638 | E7: =F7/1000000 -> 39.302266 | F7: =F8+H7+J7 -> 39302266 | G7: =H7+J7 -> 1890758.4 | H7: =H6+(H$19-H$4)/15 -> 208137.6 | I7: =J7*1000*$N$4/1000000000 -> 1.6826208 | J7: =J6+(J$19-J$4)/15 -> 1682620.8 | K7: =L7*$M$4/1000000 -> 19.162652 | L7: =L6+(L$19-L$4)/15 -> 1064591.8
A8: =A7+1 -> 4 | B8: =B7+1 -> 2018 | C8: =(D8*G8+D9*F9)/F8 -> 14.698649 | D8: =(K8*1000/G8*12/7*1000)+(I8/G8*7/12*1000) -> 15.877363 | E8: =F8/1000000 -> 37.411507 | F8: =F9+H8+J8 -> 37411507 | G8: =H8+J8 -> 2079507.2 | H8: =H7+(H$19-H$4)/15 -> 214444.8 | I8: =J8*1000*$N$4/1000000000 -> 1.8650624 | J8: =J7+(J$19-J$4)/15 -> 1865062.4 | K8: =L8*$M$4/1000000 -> 19.259335 | L8: =L7+(L$19-L$4)/15 -> 1069963.1
A9: =A8+1 -> 5 | B9: =B8+1 -> 2019 | C9: =(D9*G9+D10*F10)/F9 -> 13.640758 | D9: =(K9*1000/G9*12/7*1000)+(I9/G9*7/12*1000) -> 14.629274 | E9: =F9/1000000 -> 35.332 | F9: =F10+H9+J9 -> 35332000 | G9: =H9+J9 -> 2268256 | H9: =H8+(H$19-H$4)/15 -> 220752 | I9: =J9*1000*$N$4/1000000000 -> 2.047504 | J9: =J8+(J$19-J$4)/15 -> 2047504 | K9: =L9*$M$4/1000000 -> 19.356018 | L9: =L8+(L$19-L$4)/15 -> 1075334.3
A10: =A9+1 -> 6 | B10: =B9+1 -> 2020 | C10: =(D10*G10+D11*F11)/F10 -> 12.734628 | D10: =(K10*1000/G10*12/7*1000)+(I10/G10*7/12*1000) -> 13.572944 | E10: =F10/1000000 -> 33.063744 | F10: =F11+H10+J10 -> 33063744 | G10: =H10+J10 -> 2457004.8 | H10: =H9+(H$19-H$4)/15 -> 227059.2 | I10: =J10*1000*$N$4/1000000000 -> 2.2299456 | J10: =J9+(J$19-J$4)/15 -> 2229945.6 | K10: =L10*$M$4/1000000 -> 19.452701 | L10: =L9+(L$19-L$4)/15 -> 1080705.6
A11: =A10+1 -> 7 | B11: =B10+1 -> 2021 | C11: =(D11*G11+D12*F12)/F11 -> 11.950186 | D11: =(K11*1000/G11*12/7*1000)+(I11/G11*7/12*1000) -> 12.667331 | E11: =F11/1000000 -> 30.606739 | F11: =F12+H11+J11 -> 30606739 | G11: =H11+J11 -> 2645753.6 | H11: =H10+(H$19-H$4)/15 -> 233366.4 | I11: =J11*1000*$N$4/1000000000 -> 2.4123872 | J11: =J10+(J$19-J$4)/15 -> 2412387.2 | K11: =L11*$M$4/1000000 -> 19.549384 | L11: =L10+(L$19-L$4)/15 -> 1086076.9
A12: =A11+1 -> 8 | B12: =B11+1 -> 2022 | C12: =(D12*G12+D13*F13)/F12 -> 11.264985 | D12: =(K12*1000/G12*12/7*1000)+(I12/G12*7/12*1000) -> 11.882327 | E12: =F12/1000000 -> 27.960986 | F12: =F13+H12+J12 -> 27960986 | G12: =H12+J12 -> 2834502.4 | H12: =H11+(H$19-H$4)/15 -> 239673.6 | I12: =J12*1000*$N$4/1000000000 -> 2.5948288 | J12: =J11+(J$19-J$4)/15 -> 2594828.8 | K12: =L12*$M$4/1000000 -> 19.646066 | L12: =L11+(L$19-L$4)/15 -> 1091448.1
A13: =A12+1 -> 9 | B13: =B12+1 -> 2023 | C13: =(D13*G13+D14*F14)/F13 -> 10.662042 | D13: =(K13*1000/G13*12/7*1000)+(I13/G13*7/12*1000) -> 11.195343 | E13: =F13/1000000 -> 25.126483 | F13: =F14+H13+J13 -> 25126483 | G13: =H13+J13 -> 3023251.2 | H13: =H12+(H$19-H$4)/15 -> 245980.8 | I13: =J13*1000*$N$4/1000000000 -> 2.7772704 | J13: =J12+(J$19-J$4)/15 -> 2777270.4 | K13: =L13*$M$4/1000000 -> 19.742749 | L13: =L12+(L$19-L$4)/15 -> 1096819.4
A14: =A13+1 -> 10 | B14: =B13+1 -> 2024 | C14: =(D14*G14+D15*F15)/F14 -> 10.128467 | D14: =(K14*1000/G14*12/7*1000)+(I14/G14*7/12*1000) -> 10.589098 | E14: =F14/1000000 -> 22.103232 | F14: =F15+H14+J14 -> 22103232 | G14: =H14+J14 -> 3212000 | H14: =H13+(H$19-H$4)/15 -> 252288 | I14: =J14*1000*$N$4/1000000000 -> 2.959712 | J14: =J13+(J$19-J$4)/15 -> 2959712 | K14: =L14*$M$4/1000000 -> 19.839432 | L14: =L13+(L$19-L$4)/15 -> 1102190.7
A15: =A14+1 -> 11 | B15: =B14+1 -> 2025 | C15: =(D15*G15+D16*F16)/F15 -> 9.6546957 | D15: =(K15*1000/G15*12/7*1000)+(I15/G15*7/12*1000) -> 10.050148 | E15: =F15/1000000 -> 18.891232 | F15: =F16+H15+J15 -> 18891232 | G15: =H15+J15 -> 3400748.8 | H15: =H14+(H$19-H$4)/15 -> 258595.2 | I15: =J15*1000*$N$4/1000000000 -> 3.1421536 | J15: =J14+(J$19-J$4)/15 -> 3142153.6 | K15: =L15*$M$4/1000000 -> 19.936115 | L15: =L14+(L$19-L$4)/15 -> 1107561.9
A16: =A15+1 -> 12 | B16: =B15+1 -> 2026 | C16: =(D16*G16+D17*F17)/F16 -> 9.2343818 | D16: =(K16*1000/G16*12/7*1000)+(I16/G16*7/12*1000) -> 9.5678788 | E16: =F16/1000000 -> 15.490483 | F16: =F17+H16+J16 -> 15490483 | G16: =H16+J16 -> 3589497.6 | H16: =H15+(H$19-H$4)/15 -> 264902.4 | I16: =J16*1000*$N$4/1000000000 -> 3.3245952 | J16: =J15+(J$19-J$4)/15 -> 3324595.2 | K16: =L16*$M$4/1000000 -> 20.032798 | L16: =L15+(L$19-L$4)/15 -> 1112933.2
A17: =A16+1 -> 13 | B17: =B16+1 -> 2027 | C17: =(D17*G17+D18*F18)/F17 -> 8.8657138 | D17: =(K17*1000/G17*12/7*1000)+(I17/G17*7/12*1000) -> 9.1337946 | E17: =F17/1000000 -> 11.900986 | F17: =F18+H17+J17 -> 11900986 | G17: =H17+J17 -> 3778246.4 | H17: =H16+(H$19-H$4)/15 -> 271209.6 | I17: =J17*1000*$N$4/1000000000 -> 3.5070368 | J17: =J16+(J$19-J$4)/15 -> 3507036.8 | K17: =L17*$M$4/1000000 -> 20.12948 | L17: =L16+(L$19-L$4)/15 -> 1118304.5 | M17: 388592 | N17: Regnvann SWECO 2012
A18: =A17+1 -> 14 | B18: =B17+1 -> 2028 | C18: =(D18*G18+D19*F19)/F18 -> 8.5583196 | D18: =(K18*1000/G18*12/7*1000)+(I18/G18*7/12*1000) -> 8.7410176 | E18: =F18/1000000 -> 8.1227392 | F18: =F19+H18+J18 -> 8122739.2 | G18: =H18+J18 -> 3966995.2 | H18: =H17+(H$19-H$4)/15 -> 277516.8 | I18: =J18*1000*$N$4/1000000000 -> 3.6894784 | J18: =J17+(J$19-J$4)/15 -> 3689478.4 | K18: =L18*$M$4/1000000 -> 20.226163 | L18: =L17+(L$19-L$4)/15 -> 1123675.7 | M18: 3871920 | N18: Grundvannte BergAB20130906
A19: =A18+1 -> 15 | B19: =B18+1 -> 2029 | C19: =(D19*G19+D20*F20)/F19 -> 8.3839195 | D19: =(K19*1000/G19*12/7*1000)+(I19/G19*7/12*1000) -> 8.3839195 | E19: =F19/1000000 -> 4.155744 | F19: =F20+H19+J19 -> 4155744 | G19: =H19+J19 -> 4155744 | H19: 283824 | I19: =J19*1000*$N$4/1000000000 -> 3.87192 | J19: =M18 -> 3871920 | K19: =L19*$M$4/1000000 -> 20.322846 | L19: 1129047 | M19: 118000000 | N19: Total Lake volume after refilling
M20: 2932848 | N20: Grundvatten - bottom nytt Leveniemi, Bergab2012
M21: 283824 | N21: Regnvann SWECO 2012
M22: =6*60*60*24*365/1000 -> 189216 | N22: Regnvann Miljøbyrån 2010
M23: =36*60*60*24*365/1000 -> 1135296 | N23: Grundvatten 1983 - Miljøbyrån 2010
M24: =18*60*60*24*365/1000 -> 567648 | N24: Grundvatten 2010 - Miljøbyrån 2010
M25: 1129047 | N25: Bergyte ved nivå 55
M26: 1048478 | N26: Bergyte ved nivå 325
M29: 1860 kg/sommer | N29: 2.4 mg/l NH3
A31: Leveaniemi pit water drainge prediction
C32: NO LAKE Lake con. | D32: Summer Mean NH4 conc./year | E32: NO LAKE Lake volume | F32: NO LAKE Lake volume | G32: Yearly discharge | H32: Net Rainwater | I32: Ground water contribution | J32: Groundwater | K32: surface leaching | L32: surface area for leaching | N32: ground water
A33: # years | B33: ÅR | D33: mg/l | E33: Mm3 | F33: m3 | G33: m3/year | H33: m3/year | I33: kg/year | J33: m3/year | K33: kg/year | L33: m2 | N33: ug/l
A34: 0 | B34: 2014 | C34: =(D34*G34+D35*F35)/F34 -> 3.6304711 | D34: =(K34*1000/G34*12/7)+(I34/G34) -> 4.1300472 | E34: =F34/1000000 -> 43.842048 | F34: =F35+H34+J34 -> 43842048 | G34: =H34+J34 -> 1324512 | H34: =6*60*60*24*365/1000 -> 189216 | I34: =J34*1000*$N$34/1000000000 -> 11.35296 | J34: =36*60*60*24*365/1000 -> 1135296 | K34: 3191 | L34: 1048478 | N34: 10
A35: =A34+1 -> 1 | B35: =B34+1 -> 2015 | C35: =(D35*G35+D36*F36)/F35 -> 3.2282926 | D35: =(K35*1000/G35*12/7)+(I35/G35) -> 3.6149082 | E35: =F35/1000000 -> 42.517536 | F35: =F36+H35+J35 -> 42517536 | G35: =H35+J35 -> 1513260.8 | H35: =H34+(H$19-H$4)/15 -> 195523.2 | I35: =J35*1000*$N$34/1000000000 -> 13.177376 | J35: =J34+(J$19-J$4)/15 -> 1317737.6 | K35: 3191 | L35: =L34+(L$49-L$34)/15 -> 1053849.3 | N35: 3871920 | O35: Grundvannte BergAB20130906
A36: =A35+1 -> 2 | B36: =B35+1 -> 2016 | C36: =(D36*G36+D37*F37)/F36 -> 2.9064967 | D36: =(K36*1000/G36*12/7)+(I36/G36) -> 3.2140246 | E36: =F36/1000000 -> 41.004275 | F36: =F37+H36+J36 -> 41004275 | G36: =H36+J36 -> 1702009.6 | H36: =H35+(H$19-H$4)/15 -> 201830.4 | I36: =J36*1000*$N$34/1000000000 -> 15.001792 | J36: =J35+(J$19-J$4)/15 -> 1500179.2 | K36: 3191 | L36: =L35+(L$19-L$4)/15 -> 1059220.5 | N36: 2932848 | O36: Grundvatten - bottom nytt Leveniemi, Bergab2012
A37: =A36+1 -> 3 | B37: =B36+1 -> 2017 | C37: =(D37*G37+D38*F38)/F37 -> 2.6432105 | D37: =(K37*1000/G37*12/7)+(I37/G37) -> 2.893179 | E37: =F37/1000000 -> 39.302266 | F37: =F38+H37+J37 -> 39302266 | G37: =H37+J37 -> 1890758.4 | H37: =H36+(H$19-H$4)/15 -> 208137.6 | I37: =J37*1000*$N$34/1000000000 -> 16.826208 | J37: =J36+(J$19-J$4)/15 -> 1682620.8 | K37: 3191 | L37: =L36+(L$19-L$4)/15 -> 1064591.8 | N37: 283824 | O37: Regnvann SWECO 2012
A38: =A37+1 -> 4 | B38: =B37+1 -> 2018 | C38: =(D38*G38+D39*F39)/F38 -> 2.4238467 | D38: =(K38*1000/G38*12/7)+(I38/G38) -> 2.6305773 | E38: =F38/1000000 -> 37.411507 | F38: =F39+H38+J38 -> 37411507 | G38: =H38+J38 -> 2079507.2 | H38: =H37+(H$19-H$4)/15 -> 214444.8 | I38: =J38*1000*$N$34/1000000000 -> 18.650624 | J38: =J37+(J$19-J$4)/15 -> 1865062.4 | K38: 3191 | L38: =L37+(L$19-L$4)/15 -> 1069963.1 | N38: =6*60*60*24*365/1000 -> 189216 | O38: Regnvann Miljøbyrån 2010
A39: =A38+1 -> 5 | B39: =B38+1 -> 2019 | C39: =(D39*G39+D40*F40)/F39 -> 2.238307 | D39: =(K39*1000/G39*12/7)+(I39/G39) -> 2.4116794 | E39: =F39/1000000 -> 35.332 | F39: =F40+H39+J39 -> 35332000 | G39: =H39+J39 -> 2268256 | H39: =H38+(H$19-H$4)/15 -> 220752 | I39: =J39*1000*$N$34/1000000000 -> 20.47504 | J39: =J38+(J$19-J$4)/15 -> 2047504 | K39: 3191 | L39: =L38+(L$19-L$4)/15 -> 1075334.3 | N39: =36*60*60*24*365/1000 -> 1135296 | O39: Grundvatten 1983 - Miljøbyrån 2010
A40: =A39+1 -> 6 | B40: =B39+1 -> 2020 | C40: =(D40*G40+D41*F41)/F40 -> 2.079384 | D40: =(K40*1000/G40*12/7)+(I40/G40) -> 2.2264132 | E40: =F40/1000000 -> 33.063744 | F40: =F41+H40+J40 -> 33063744 | G40: =H40+J40 -> 2457004.8 | H40: =H39+(H$19-H$4)/15 -> 227059.2 | I40: =J40*1000*$N$34/1000000000 -> 22.299456 | J40: =J39+(J$19-J$4)/15 -> 2229945.6 | K40: 3191 | L40: =L39+(L$19-L$4)/15 -> 1080705.6 | N40: =18*60*60*24*365/1000 -> 567648 | O40: Grundvatten 2010 - Miljøbyrån 2010
A41: =A40+1 -> 7 | B41: =B40+1 -> 2021 | C41: =(D41*G41+D42*F42)/F41 -> 1.9418034 | D41: =(K41*1000/G41*12/7)+(I41/G41) -> 2.067581 | E41: =F41/1000000 -> 30.606739 | F41: =F42+H41+J41 -> 30606739 | G41: =H41+J41 -> 2645753.6 | H41: =H40+(H$19-H$4)/15 -> 233366.4 | I41: =J41*1000*$N$34/1000000000 -> 24.123872 | J41: =J40+(J$19-J$4)/15 -> 2412387.2 | K41: 3191 | L41: =L40+(L$19-L$4)/15 -> 1086076.9 | N41: 1129047 | O41: Bergyte ved nivå 55
A42: =A41+1 -> 8 | B42: =B41+1 -> 2022 | C42: =(D42*G42+D43*F43)/F42 -> 1.8216284 | D42: =(K42*1000/G42*12/7)+(I42/G42) -> 1.9299019 | E42: =F42/1000000 -> 27.960986 | F42: =F43+H42+J42 -> 27960986 | G42: =H42+J42 -> 2834502.4 | H42: =H41+(H$19-H$4)/15 -> 239673.6 | I42: =J42*1000*$N$34/1000000000 -> 25.948288 | J42: =J41+(J$19-J$4)/15 -> 2594828.8 | K42: 3191 | L42: =L41+(L$19-L$4)/15 -> 1091448.1 | N42: 1048478 | O42: Bergyte ved nivå 325
A43: =A42+1 -> 9 | B43: =B42+1 -> 2023 | C43: =(D43*G43+D44*F44)/F43 -> 1.7158804 | D43: =(K43*1000/G43*12/7)+(I43/G43) -> 1.8094141 | E43: =F43/1000000 -> 25.126483 | F43: =F44+H43+J43 -> 25126483 | G43: =H43+J43 -> 3023251.2 | H43: =H42+(H$19-H$4)/15 -> 245980.8 | I43: =J43*1000*$N$34/1000000000 -> 27.772704 | J43: =J42+(J$19-J$4)/15 -> 2777270.4 | K43: 3191 | L43: =L42+(L$19-L$4)/15 -> 1096819.4 | N43: 25000000 | O43: Årsflødet i Liukattijoki m3/år
...

Sheet Mod after closure
A1: Leveaniemi pit lake water quality prediction
C2: COPPER Lake conc. | D2: Mean Copper conc./year | E2: Lake volume | F2: Lake volume | G2: Yearly discharge | H2: Net Rainwater | I2: Groundwater contribution | J2: Groundwater | K2: surface leaching | L2: Ratio GW change | N2: Neg. Expon. surface area for leaching | O2: Linear surface area for leaching | P2: Leaching | Q2: ground water
A3: # years | B3: ÅR | D3: ug/l | E3: Mm3 | F3: m3 | G3: m3/year | H3: m3/year | I3: kg/year | J3: m3/year | K3: kg/year | N3: m2 | O3: m2 | P3: mg/m2/year | Q3: ug/l
A4: 0 | B4: 2029 | C4: =(D4*G4)/F4 -> 5.7424186 | D4: =(M4+I4)*1000/G4*1000 -> 5.7424186 | E4: =F4/1000000 -> 3.847392 | F4: =H4+J4 -> 3847392 | G4: =H4+J4 -> 3847392 | H4: 283824 | I4: =J4*1000*$Q$4/1000000000 -> 0.64144224 | J4: 3563568 | K4: =N4*$P$4/1000000 -> 21.451893 | M4: =P4*$N$4/1000000 -> 21.451893 | N4: 1129047 | O4: 1129047 | P4: 19 | Q4: 0.18 | X4: BERGAB
A5: =A4+1 -> 1 | B5: =B4+1 -> 2030 | C5: =(D5*G5+D4*F4)/F5 -> 10.976658 | D5: =(K5+I5)*1000/G5*1000 -> 5.7015828 | E5: =F5/1000000 -> 3.847392 | F5: =H4+J4 -> 3847392 | G5: =H5+J5 -> 3532032 | H5: =$P$21 -> 283824 | I5: =J5*1000*$Q$4/1000000000 -> 0.58467744 | J5: 3248208 | K5: =N5*$P$4/1000000 -> 19.553495 | L5: =J5/J4 -> 0.91150442 | M5: =N5*$P$4/1000000 -> 19.553495 | N5: =O4*L5 -> 1029131.3 | O5: =O4+(O$154-O$4)/150 -> 1122453.4 | U5: 2014
A6: =A5+1 -> 2 | B6: =B5+1 -> 2031 | C6: =(D6*G6+D5*F5)/F6 -> 5.8265511 | D6: =(K6+I6)*1000/G6*1000 -> 6.1835173 | E6: =F6/1000000 -> 7.379424 | F6: =F5+H5+J5 -> 7379424 | G6: =H6+J6 -> 3405888 | H6: =$P$21 -> 283824 | I6: =J6*1000*$Q$4/1000000000 -> 0.56197152 | J6: 3122064 | K6: =N6*$P$4/1000000 -> 20.498396 | L6: =J6/J5 -> 0.96116505 | M6: =N6*$P$4/1000000 -> 20.498396 | N6: =O5*L6 -> 1078862.9 | O6: =O5+(O$154-O$4)/150 -> 1115859.7 | P6: NIVÅ | Q6: L/s | S6: Mm3/year | T6: Volum m3 | U6: Year | X6: Level | Y6: Groundwater | AA6: Rainwater (9 l/s) | AB6: Total | AC6: Lake volume | AE6: Filling time
A7: =A6+1 -> 3 | B7: =B6+1 -> 2032 | C7: =(D7*G7+D6*F6)/F7 -> 6.0652505 | D7: =(K7+I7)*1000/G7*1000 -> 6.3370974 | E7: =F7/1000000 -> 10.785312 | F7: =F6+H6+J6 -> 10785312 | G7: =H7+J7 -> 3122064 | H7: =$P$21 -> 283824 | I7: =J7*1000*$Q$4/1000000000 -> 0.5108832 | J7: 2838240 | K7: =N7*$P$4/1000000 -> 19.27394 | L7: =J7/J6 -> 0.90909091 | M7: =N7*$P$4/1000000 -> 19.27394 | N7: =O6*L7 -> 1014417.9 | O7: =O6+(O$154-O$4)/150 -> 1109266.1 | P7: 340 | Q7: 5 | R7: =Q7*60*60*24*365/1000 -> 157680 | S7: =Q7*60*60*24*365/1000000000 -> 0.15768 | T7: 116805 | U7: 150 | V7: =2029+U7 -> 2179 | Y7: l/s | Z7: m3/year | AA7: m3/year | AB7: m3/year | AC7: acc. m3 | AD7: difference m3 | AE7: years | AF7: acc. Years
A8: =A7+1 -> 4 | B8: =B7+1 -> 2033 | C8: =(D8*G8+D7*F7)/F8 -> 6.4091885 | D8: =(K8+I8)*1000/G8*1000 -> 6.8902247 | E8: =F8/1000000 -> 13.907376 | F8: =F7+H7+J7 -> 13907376 | G8: =H8+J8 -> 3016944 | H8: =$P$21 -> 283824 | I8: =J8*1000*$Q$4/1000000000 -> 0.4919616 | J8: =J7+(J$10-J$7)/3 -> 2733120 | K8: =N8*$P$4/1000000 -> 20.295461 | L8: =J8/J7 -> 0.96296296 | M8: =N8*$P$4/1000000 -> 20.295461 | N8: =O7*L8 -> 1068182.1 | O8: =O7+(O$154-O$4)/150 -> 1102672.4 | P8: 310 | Q8: 17 | R8: =Q8*60*60*24*365/1000 -> 536112 | S8: =Q8*60*60*24*365/1000000000 -> 0.536112 | T8: 93047 | U8: 75 | V8: =2029+U8 -> 2104 | X8: 340 | Y8: 0 | Z8: =Y8*3600*24*365/1000 -> 0 | AA8: =9*3600*24*365/1000 -> 283824 | AB8: =Z8+AA8 -> 283824 | AC8: 116805000 | AD8: 23758000 | AE8: =AD8/AB8 -> 83.706804 | AF8: =AE8+AF9 -> 146.4923
A9: =A8+1 -> 5 | B9: =B8+1 -> 2034 | C9: =(D9*G9+D8*F8)/F9 -> 6.8802151 | D9: =(K9+I9)*1000/G9*1000 -> 7.0807909 | E9: =F9/1000000 -> 16.92432 | F9: =F8+H8+J8 -> 16924320 | G9: =H9+J9 -> 2911824 | H9: =$P$21 -> 283824 | I9: =J9*1000*$Q$4/1000000000 -> 0.47304 | J9: =J8+(J$10-J$7)/3 -> 2628000 | K9: =N9*$P$4/1000000 -> 20.144977 | L9: =J9/J8 -> 0.96153846 | M9: =N9*$P$4/1000000 -> 20.144977 | N9: =O8*L9 -> 1060261.9 | O9: =O8+(O$154-O$4)/150 -> 1096078.8 | P9: 280 | Q9: 32 | R9: =Q9*60*60*24*365/1000 -> 1009152 | S9: =Q9*60*60*24*365/1000000000 -> 1.009152 | T9: 72479 | U9: 48 | V9: =2029+U9 -> 2077 | X9: 310 | Y9: 17 | Z9: =Y9*3600*24*365/1000 -> 536112 | AA9: =9*3600*24*365/1000 -> 283824 | AB9: =Z9+AA9 -> 819936 | AC9: 93047000 | AD9: 20568000 | AE9: =AD9/AB9 -> 25.084885 | AF9: =AE9+AF10 -> 62.785497
A10: =A9+1 -> 6 | B10: =B9+1 -> 2035 | C10: =(D10*G10+D9*F9)/F10 -> 7.072149 | D10: =(K10+I10)*1000/G10*1000 -> 7.2849132 | E10: =F10/1000000 -> 19.836144 | F10: =F9+H9+J9 -> 19836144 | G10: =H10+J10 -> 2806704 | H10: =$P$21 -> 283824 | I10: =J10*1000*$Q$4/1000000000 -> 0.4541184 | J10: 2522880 | K10: =N10*$P$4/1000000 -> 19.992477 | L10: =J10/J9 -> 0.96 | M10: =N10*$P$4/1000000 -> 19.992477 | N10: =O9*L10 -> 1052235.6 | O10: =O9+(O$154-O$4)/150 -> 1089485.1 | P10: 250 | Q10: 46 | R10: =Q10*60*60*24*365/1000 -> 1450656 | S10: =Q10*60*60*24*365/1000000000 -> 1.450656 | T10: 54889 | U10: 33 | V10: =2029+U10 -> 2062 | X10: 280 | Y10: 32 | Z10: =Y10*3600*24*365/1000 -> 1009152 | AA10: =9*3600*24*365/1000 -> 283824 | AB10: =Z10+AA10 -> 1292976 | AC10: 72479000 | AD10: 17589000 | AE10: =AD10/AB10 -> 13.603501 | AF10: =AE10+AF11 -> 37.700612
A11: =A10+1 -> 7 | B11: =B10+1 -> 2036 | C11: =(D11*G11+D10*F10)/F11 -> 7.2869743 | D11: =(K11+I11)*1000/G11*1000 -> 6.732258 | E11: =F11/1000000 -> 22.642848 | F11: =F10+H10+J10 -> 22642848 | G11: =H11+J11 -> 3044040 | H11: 600000 | I11: =J11*1000*$Q$4/1000000000 -> 0.4399272 | J11: =J10+(J$14-J$10)/4 -> 2444040 | K11: =N11*$P$4/1000000 -> 20.053335 | L11: =J11/J10 -> 0.96875 | M11: =N11*$P$4/1000000 -> 20.053335 | N11: =O10*L11 -> 1055438.7 | O11: =O10+(O$154-O$4)/150 -> 1082891.5 | P11: 220 | Q11: 58 | R11: =Q11*60*60*24*365/1000 -> 1829088 | S11: =Q11*60*60*24*365/1000000000 -> 1.829088 | T11: 40096 | U11: 23 | V11: =2029+U11 -> 2052 | X11: 250 | Y11: 46 | Z11: =Y11*3600*24*365/1000 -> 1450656 | AA11: =9*3600*24*365/1000 -> 283824 | AB11: =Z11+AA11 -> 1734480 | AC11: 54889000 | AD11: 14793000 | AE11: =AD11/AB11 -> 8.528781 | AF11: =AE11+AF12 -> 24.097111
A12: =A11+1 -> 8 | B12: =B11+1 -> 2037 | C12: =(D12*G12+D11*F11)/F12 -> 6.7261733 | D12: =(K12+I12)*1000/G12*1000 -> 6.8585479 | E12: =F12/1000000 -> 25.686888 | F12: =F11+H11+J11 -> 25686888 | G12: =H12+J12 -> 2965200 | H12: 600000 | I12: =J12*1000*$Q$4/1000000000 -> 0.425736 | J12: =J11+(J$14-J$10)/4 -> 2365200 | K12: =N12*$P$4/1000000 -> 19.91123 | L12: =J12/J11 -> 0.96774194 | M12: =N12*$P$4/1000000 -> 19.91123 | N12: =O11*L12 -> 1047959.5 | O12: =O11+(O$154-O$4)/150 -> 1076297.8 | P12: 190 | Q12: 70 | R12: =Q12*60*60*24*365/1000 -> 2207520 | S12: =Q12*60*60*24*365/1000000000 -> 2.20752 | T12: 27965 | U12: 16 | V12: =2029+U12 -> 2045 | X12: 220 | Y12: 58 | Z12: =Y12*3600*24*365/1000 -> 1829088 | AA12: =9*3600*24*365/1000 -> 283824 | AB12: =Z12+AA12 -> 2112912 | AC12: 40096000 | AD12: 12131000 | AE12: =AD12/AB12 -> 5.7413655 | AF12: =AE12+AF13 -> 15.56833
A13: =A12+1 -> 9 | B13: =B12+1 -> 2038 | C13: =(D13*G13+D12*F12)/F13 -> 6.8530538 | D13: =(K13+I13)*1000/G13*1000 -> 7.8514022 | E13: =F13/1000000 -> 28.652088 | F13: =F12+H12+J12 -> 28652088 | G13: =H13+J13 -> 2570184 | H13: =$P$21 -> 283824 | I13: =J13*1000*$Q$4/1000000000 -> 0.4115448 | J13: =J12+(J$14-J$10)/4 -> 2286360 | K13: =N13*$P$4/1000000 -> 19.768003 | L13: =J13/J12 -> 0.96666667 | M13: =N13*$P$4/1000000 -> 19.768003 | N13: =O12*L13 -> 1040421.2 | O13: =O12+(O$154-O$4)/150 -> 1069704.2 | P13: 160 | Q13: 80 | R13: =Q13*60*60*24*365/1000 -> 2522880 | S13: =Q13*60*60*24*365/1000000000 -> 2.52288 | T13: 18194 | U13: 10 | V13: =2029+U13 -> 2039 | X13: 190 | Y13: 70 | Z13: =Y13*3600*24*365/1000 -> 2207520 | AA13: =9*3600*24*365/1000 -> 283824 | AB13: =Z13+AA13 -> 2491344 | AC13: 27965000 | AD13: 9771000 | AE13: =AD13/AB13 -> 3.9219795 | AF13: =AE13+AF14 -> 9.8269649
A14: =A13+1 -> 10 | B14: =B13+1 -> 2039 | C14: =(D14*G14+D13*F13)/F14 -> 7.8463207 | D14: =(K14+I14)*1000/G14*1000 -> 8.0361814 | E14: =F14/1000000 -> 31.222272 | F14: =F13+H13+J13 -> 31222272 | G14: =H14+J14 -> 2491344 | H14: =$P$21 -> 283824 | I14: =J14*1000*$Q$4/1000000000 -> 0.3973536 | J14: 2207520 | K14: =N14*$P$4/1000000 -> 19.623539 | L14: =J14/J13 -> 0.96551724 | M14: =N14*$P$4/1000000 -> 19.623539 | N14: =O13*L14 -> 1032817.8 | O14: =O13+(O$154-O$4)/150 -> 1063110.5 | P14: 130 | Q14: 90 | R14: =Q14*60*60*24*365/1000 -> 2838240 | S14: =Q14*60*60*24*365/1000000000 -> 2.83824 | T14: 10671 | U14: 5 | V14: =2029+U14 -> 2034 | X14: 160 | Y14: 80 | Z14: =Y14*3600*24*365/1000 -> 2522880 | AA14: =9*3600*24*365/1000 -> 283824 | AB14: =Z14+AA14 -> 2806704 | AC14: 18194000 | AD14: 7523000 | AE14: =AD14/AB14 -> 2.6803681 | AF14: =AE14+AF15 -> 5.9049855
A15: =A14+1 -> 11 | B15: =B14+1 -> 2040 | C15: =(D15*G15+D14*F14)/F15 -> 8.0357985 | D15: =(K15+I15)*1000/G15*1000 -> 8.2395974 | E15: =F15/1000000 -> 33.713616 | F15: =F14+H14+J14 -> 33713616 | G15: =H15+J15 -> 2428272 | H15: =$P$21 -> 283824 | I15: =J15*1000*$Q$4/1000000000 -> 0.38600064 | J15: =J14+(J$20-J$14)/6 -> 2144448 | K15: =N15*$P$4/1000000 -> 19.621983 | L15: =J15/J14 -> 0.97142857 | M15: =N15*$P$4/1000000 -> 19.621983 | N15: =O14*L15 -> 1032735.9 | O15: =O14+(O$154-O$4)/150 -> 1056516.9 | P15: 100 | Q15: 99 | R15: =Q15*60*60*24*365/1000 -> 3122064 | S15: =Q15*60*60*24*365/1000000000 -> 3.122064 | T15: 5226 | U15: 3 | V15: =2029+U15 -> 2032 | X15: 130 | Y15: 90 | Z15: =Y15*3600*24*365/1000 -> 2838240 | AA15: =9*3600*24*365/1000 -> 283824 | AB15: =Z15+AA15 -> 3122064 | AC15: 10671000 | AD15: 5445000 | AE15: =AD15/AB15 -> 1.7440386 | AF15: =AE15+AF16 -> 3.2246173
A16: =A15+1 -> 12 | B16: =B15+1 -> 2041 | C16: =(D16*G16+D15*F15)/F16 -> 8.2354492 | D16: =(K16+I16)*1000/G16*1000 -> 8.3959335 | E16: =F16/1000000 -> 36.141888 | F16: =F15+H15+J15 -> 36141888 | G16: =H16+J16 -> 2365200 | H16: =$P$21 -> 283824 | I16: =J16*1000*$Q$4/1000000000 -> 0.37464768 | J16: =J15+(J$20-J$14)/6 -> 2081376 | K16: =N16*$P$4/1000000 -> 19.483414 | L16: =J16/J15 -> 0.97058824 | M16: =N16*$P$4/1000000 -> 19.483414 | N16: =O15*L16 -> 1025442.9 | O16: =O15+(O$154-O$4)/150 -> 1049923.2 | P16: 85 | Q16: 103 | R16: =Q16*60*60*24*365/1000 -> 3248208 | S16: =Q16*60*60*24*365/1000000000 -> 3.248208 | T16: 3312 | U16: 2 | V16: =2029+U16 -> 2031 | X16: 100 | Y16: 99 | Z16: =Y16*3600*24*365/1000 -> 3122064 | AA16: =9*3600*24*365/1000 -> 283824 | AB16: =Z16+AA16 -> 3405888 | AC16: 5226000 | AD16: 1914000 | AE16: =AD16/AB16 -> 0.56196798 | AF16: =AE16+AF17 -> 1.4805787
A17: =A16+1 -> 13 | B17: =B16+1 -> 2042 | C17: =(D17*G17+D16*F16)/F17 -> 8.3920193 | D17: =(K17+I17)*1000/G17*1000 -> 9.0888247 | E17: =F17/1000000 -> 38.507088 | F17: =F16+H16+J16 -> 38507088 | G17: =H17+J17 -> 2168304 | H17: 150000 | I17: =J17*1000*$Q$4/1000000000 -> 0.36329472 | J17: =J16+(J$20-J$14)/6 -> 2018304 | K17: =N17*$P$4/1000000 -> 19.34404 | L17: =J17/J16 -> 0.96969697 | M17: =N17*$P$4/1000000 -> 19.34404 | N17: =O16*L17 -> 1018107.4 | O17: =O16+(O$154-O$4)/150 -> 1043329.6 | P17: 75 | Q17: 105 | R17: =Q17*60*60*24*365/1000 -> 3311280 | S17: =Q17*60*60*24*365/1000000000 -> 3.31128 | T17: 2190 | U17: 1.5 | V17: =2029+U17 -> 2030.5 | X17: 85 | Y17: 103 | Z17: =Y17*3600*24*365/1000 -> 3248208 | AA17: =9*3600*24*365/1000 -> 283824 | AB17: =Z17+AA17 -> 3532032 | AC17: 3312000 | AD17: 1122000 | AE17: =AD17/AB17 -> 0.31766417 | AF17: =AE17+AF18 -> 0.91861076
A18: =A17+1 -> 14 | B18: =B17+1 -> 2043 | C18: =(D18*G18+D17*F17)/F18 -> 9.0850975 | D18: =(K18+I18)*1000/G18*1000 -> 9.2891078 | E18: =F18/1000000 -> 40.675392 | F18: =F17+H17+J17 -> 40675392 | G18: =H18+J18 -> 2105232 | H18: 150000 | I18: =J18*1000*$Q$4/1000000000 -> 0.35194176 | J18: =J17+(J$20-J$14)/6 -> 1955232 | K18: =N18*$P$4/1000000 -> 19.203785 | L18: =J18/J17 -> 0.96875 | M18: =N18*$P$4/1000000 -> 19.203785 | N18: =O17*L18 -> 1010725.5 | O18: =O17+(O$154-O$4)/150 -> 1036735.9 | P18: 70 | Q18: 107 | R18: =Q18*60*60*24*365/1000 -> 3374352 | S18: =Q18*60*60*24*365/1000000000 -> 3.374352 | T18: 1713 | U18: 1 | V18: =2029+U18 -> 2030 | X18: 75 | Y18: 105 | Z18: =Y18*3600*24*365/1000 -> 3311280 | AA18: =9*3600*24*365/1000 -> 283824 | AB18: =Z18+AA18 -> 3595104 | AC18: 2190000 | AD18: 477000 | AE18: =AD18/AB18 -> 0.13268045 | AF18: =AE18+AF19 -> 0.6009466
A19: =A18+1 -> 15 | B19: =B18+1 -> 2044 | C19: =(D19*G19+D18*F18)/F19 -> 9.2855414 | D19: =(K19+I19)*1000/G19*1000 -> 8.9169557 | E19: =F19/1000000 -> 42.780624 | F19: =F18+H18+J18 -> 42780624 | G19: =H19+J19 -> 2175984 | H19: =$P$21 -> 283824 | I19: =J19*1000*$Q$4/1000000000 -> 0.3405888 | J19: =J18+(J$20-J$14)/6 -> 1892160 | K19: =N19*$P$4/1000000 -> 19.062564 | L19: =J19/J18 -> 0.96774194 | M19: =N19*$P$4/1000000 -> 19.062564 | N19: =O18*L19 -> 1003292.9 | O19: =O18+(O$154-O$4)/150 -> 1030142.3 | P19: 40 | Q19: 113 | R19: =Q19*60*60*24*365/1000 -> 3563568 | S19: =Q19*60*60*24*365/1000000000 -> 3.563568 | T19: 0 | U19: 0 | V19: =2029+U19 -> 2029 | X19: 70 | Y19: 107 | Z19: =Y19*3600*24*365/1000 -> 3374352 | AA19: =9*3600*24*365/1000 -> 283824 | AB19: =Z19+AA19 -> 3658176 | AC19: 1713000 | AD19: 1713000 | AE19: =AD19/AB19 -> 0.46826615 | AF19: =AE19+AF20 -> 0.46826615
A20: =A19+1 -> 16 | B20: =B19+1 -> 2045 | C20: =(D20*G20+D19*F19)/F20 -> 8.9135383 | D20: =(K20+I20)*1000/G20*1000 -> 9.1104202 | E20: =F20/1000000 -> 44.956608 | F20: =F19+H19+J19 -> 44956608 | G20: =H20+J20 -> 2112912 | H20: =$P$21 -> 283824 | I20: =J20*1000*$Q$4/1000000000 -> 0.32923584 | J20: 1829088 | K20: =N20*$P$4/1000000 -> 18.92028 | L20: =J20/J19 -> 0.96666667 | M20: =N20*$P$4/1000000 -> 18.92028 | N20: =O19*L20 -> 995804.22 | O20: =O19+(O$154-O$4)/150 -> 1023548.7 | X20: 40 | Y20: 113 | Z20: =Y20*3600*24*365/1000 -> 3563568 | AA20: =9*3600*24*365/1000 -> 283824 | AB20: =Z20+AA20 -> 3847392 | AC20: 0 | AD20: 0 | AE20: =AD20/AB20 -> 0 | AF20: =AE20 -> 0
A21: =A20+1 -> 17 | B21: =B20+1 -> 2046 | C21: =(D21*G21+D20*F20)/F21 -> 9.1107533 | D21: =(K21+I21)*1000/G21*1000 -> 9.3266462 | E21: =F21/1000000 -> 47.06952 | F21: =F20+H20+J20 -> 47069520 | G21: =H21+J21 -> 2065608 | H21: =$P$21 -> 283824 | I21: =J21*1000*$Q$4/1000000000 -> 0.32072112 | J21: =J20+(J$28-J$20)/8 -> 1781784 | K21: =N21*$P$4/1000000 -> 18.944474 | L21: =J21/J20 -> 0.97413793 | M21: =N21*$P$4/1000000 -> 18.944474 | N21: =O20*L21 -> 997077.57 | O21: =O20+(O$154-O$4)/150 -> 1016955 | P21: 283824 | Q21: Regnvann SWECO 2012
A22: =A21+1 -> 18 | B22: =B21+1 -> 2047 | C22: =(D22*G22+D21*F21)/F22 -> 9.3237191 | D22: =(K22+I22)*1000/G22*1000 -> 9.4739812 | E22: =F22/1000000 -> 49.135128 | F22: =F21+H21+J21 -> 49135128 | G22: =H22+J22 -> 2018304 | H22: =$P$21 -> 283824 | I22: =J22*1000*$Q$4/1000000000 -> 0.3122064 | J22: =J21+(J$28-J$20)/8 -> 1734480 | K22: =N22*$P$4/1000000 -> 18.809168 | L22: =J22/J21 -> 0.97345133 | M22: =N22*$P$4/1000000 -> 18.809168 | N22: =O21*L22 -> 989956.2 | O22: =O21+(O$154-O$4)/150 -> 1010361.4 | P22: =6*60*60*24*365/1000 -> 189216 | Q22: Regnvann Miljøbyrån 2010
A23: =A22+1 -> 19 | B23: =B22+1 -> 2048 | C23: =(D23*G23+D22*F22)/F23 -> 9.471159 | D23: =(K23+I23)*1000/G23*1000 -> 9.6281109 | E23: =F23/1000000 -> 51.153432 | F23: =F22+H22+J22 -> 51153432 | G23: =H23+J23 -> 1971000 | H23: =$P$21 -> 283824 | I23: =J23*1000*$Q$4/1000000000 -> 0.30369168 | J23: =J22+(J$28-J$20)/8 -> 1687176 | K23: =N23*$P$4/1000000 -> 18.673315 | L23: =J23/J22 -> 0.97272727 | M23: =N23*$P$4/1000000 -> 18.673315 | N23: =O22*L23 -> 982806.05 | O23: =O22+(O$154-O$4)/150 -> 1003767.7 | P23: =36*60*60*24*365/1000 -> 1135296 | Q23: Grundvatten 1983 - Miljøbyrån 2010
A24: =A23+1 -> 20 | B24: =B23+1 -> 2049 | C24: =(D24*G24+D23*F23)/F24 -> 9.6253822 | D24: =(K24+I24)*1000/G24*1000 -> 9.7895125 | E24: =F24/1000000 -> 53.124432 | F24: =F23+H23+J23 -> 53124432 | G24: =H24+J24 -> 1923696 | H24: =$P$21 -> 283824 | I24: =J24*1000*$Q$4/1000000000 -> 0.29517696 | J24: =J23+(J$28-J$20)/8 -> 1639872 | K24: =N24*$P$4/1000000 -> 18.536869 | L24: =J24/J23 -> 0.97196262 | M24: =N24*$P$4/1000000 -> 18.536869 | N24: =O23*L24 -> 975624.69 | O24: =O23+(O$154-O$4)/150 -> 997174.07 | P24: =18*60*60*24*365/1000 -> 567648 | Q24: Grundvatten 2010 - Miljøbyrån 2010
A25: =A24+1 -> 21 | B25: =B24+1 -> 2050 | C25: =(D25*G25+D24*F24)/F25 -> 9.7868675 | D25: =(K25+I25)*1000/G25*1000 -> 9.9587087 | E25: =F25/1000000 -> 55.048128 | F25: =F24+H24+J24 -> 55048128 | G25: =H25+J25 -> 1876392 | H25: =$P$21 -> 283824 | I25: =J25*1000*$Q$4/1000000000 -> 0.28666224 | J25: =J24+(J$28-J$20)/8 -> 1592568 | K25: =N25*$P$4/1000000 -> 18.399779 | L25: =J25/J24 -> 0.97115385 | M25: =N25*$P$4/1000000 -> 18.399779 | N25: =O24*L25 -> 968409.43 | O25: =O24+(O$154-O$4)/150 -> 990580.42 | P25: 1129047 | Q25: Bergyte ved nivå 55
A26: =A25+1 -> 22 | B26: =B25+1 -> 2051 | C26: =(D26*G26+D25*F25)/F26 -> 9.9561386 | D26: =(K26+I26)*1000/G26*1000 -> 10.136273 | E26: =F26/1000000 -> 56.92452 | F26: =F25+H25+J25 -> 56924520 | G26: =H26+J26 -> 1829088 | H26: =$P$21 -> 283824 | I26: =J26*1000*$Q$4/1000000000 -> 0.27814752 | J26: =J25+(J$28-J$20)/8 -> 1545264 | K26: =N26*$P$4/1000000 -> 18.261988 | L26: =J26/J25 -> 0.97029703 | M26: =N26*$P$4/1000000 -> 18.261988 | N26: =O25*L26 -> 961157.24 | O26: =O25+(O$154-O$4)/150 -> 983986.77 | P26: 1048478 | Q26: Bergyte ved nivå 325
A27: =A26+1 -> 23 | B27: =B26+1 -> 2052 | C27: =(D27*G27+D26*F26)/F27 -> 10.13377 | D27: =(K27+I27)*1000/G27*1000 -> 10.322835 | E27: =F27/1000000 -> 58.753608 | F27: =F26+H26+J26 -> 58753608 | G27: =H27+J27 -> 1781784 | H27: =$P$21 -> 283824 | I27: =J27*1000*$Q$4/1000000000 -> 0.2696328 | J27: =J26+(J$28-J$20)/8 -> 1497960 | K27: =N27*$P$4/1000000 -> 18.12343 | L27: =J27/J26 -> 0.96938776 | M27: =N27*$P$4/1000000 -> 18.12343 | N27: =O26*L27 -> 953864.73 | O27: =O26+(O$154-O$4)/150 -> 977393.13 | P27: 281216 | Q27: Bergyte ved nivå 325 over vannspeil 2012
A28: =A27+1 -> 24 | B28: =B27+1 -> 2053 | C28: =(D28*G28+D27*F27)/F28 -> 10.320392 | D28: =(K28+I28)*1000/G28*1000 -> 10.51909 | E28: =F28/1000000 -> 60.535392 | F28: =F27+H27+J27 -> 60535392 | G28: =H28+J28 -> 1734480 | H28: =$P$21 -> 283824 | I28: =J28*1000*$Q$4/1000000000 -> 0.26111808 | J28: 1450656 | K28: =N28*$P$4/1000000 -> 17.984034 | L28: =J28/J27 -> 0.96842105 | M28: =N28*$P$4/1000000 -> 17.984034 | N28: =O27*L28 -> 946528.08 | O28: =O27+(O$154-O$4)/150 -> 970799.48 | P28: 140000 | Q28: Bergyte ved nivå 340 over vannspeil 2170
A29: =A28+1 -> 25 | B29: =B28+1 -> 2054 | C29: =(D29*G29+D28*F28)/F29 -> 10.518184 | D29: =(K29+I29)*1000/G29*1000 -> 10.734981 | E29: =F29/1000000 -> 62.269872 | F29: =F28+H28+J28 -> 62269872 | G29: =H29+J29 -> 1694343.3 | H29: =$P$21 -> 283824 | I29: =J29*1000*$Q$4/1000000000 -> 0.25389347 | J29: =J28+(J$38-J$28)/11 -> 1410519.3 | K29: =N29*$P$4/1000000 -> 17.934849 | L29: =J29/J28 -> 0.97233202 | M29: =N29*$P$4/1000000 -> 17.934849 | N29: =O28*L29 -> 943939.42 | O29: =O28+(O$154-O$4)/150 -> 964205.83
A30: =A29+1 -> 26 | B30: =B29+1 -> 2055 | C30: =(D30*G30+D29*F29)/F30 -> 10.732738 | D30: =(K30+I30)*1000/G30*1000 -> 10.908723 | E30: =F30/1000000 -> 63.964215 | F30: =F29+H29+J29 -> 63964215 | G30: =H30+J30 -> 1654206.5 | H30: =$P$21 -> 283824 | I30: =J30*1000*$Q$4/1000000000 -> 0.24666886 | J30: =J29+(J$38-J$28)/11 -> 1370382.5 | K30: =N30*$P$4/1000000 -> 17.798613 | L30: =J30/J29 -> 0.97154472 | M30: =N30*$P$4/1000000 -> 17.798613 | N30: =O29*L30 -> 936769.08 | O30: =O29+(O$154-O$4)/150 -> 957612.19
A31: =A30+1 -> 27 | B31: =B30+1 -> 2056 | C31: =(D31*G31+D30*F30)/F31 -> 10.906527 | D31: =(K31+I31)*1000/G31*1000 -> 11.090709 | E31: =F31/1000000 -> 65.618422 | F31: =F30+H30+J30 -> 65618422 | G31: =H31+J31 -> 1614069.8 | H31: =$P$21 -> 283824 | I31: =J31*1000*$Q$4/1000000000 -> 0.23944425 | J31: =J30+(J$38-J$28)/11 -> 1330245.8 | K31: =N31*$P$4/1000000 -> 17.661734 | L31: =J31/J30 -> 0.9707113 | M31: =N31*$P$4/1000000 -> 17.661734 | N31: =O30*L31 -> 929564.97 | O31: =O30+(O$154-O$4)/150 -> 951018.54
A32: =A31+1 -> 28 | B32: =B31+1 -> 2057 | C32: =(D32*G32+D31*F31)/F32 -> 11.088555 | D32: =(K32+I32)*1000/G32*1000 -> 11.281532 | E32: =F32/1000000 -> 67.232492 | F32: =F31+H31+J31 -> 67232492 | G32: =H32+J32 -> 1573933.1 | H32: =$P$21 -> 283824 | I32: =J32*1000*$Q$4/1000000000 -> 0.23221964 | J32: =J31+(J$38-J$28)/11 -> 1290109.1 | K32: =N32*$P$4/1000000 -> 17.524156 | L32: =J32/J31 -> 0.96982759 | M32: =N32*$P$4/1000000 -> 17.524156 | N32: =O31*L32 -> 922324.02 | O32: =O31+(O$154-O$4)/150 -> 944424.89
A33: =A32+1 -> 29 | B33: =B32+1 -> 2058 | C33: =(D33*G33+D32*F32)/F33 -> 11.279416 | D33: =(K33+I33)*1000/G33*1000 -> 11.481842 | E33: =F33/1000000 -> 68.806425 | F33: =F32+H32+J32 -> 68806425 | G33: =H33+J33 -> 1533796.4 | H33: =$P$21 -> 283824 | I33: =J33*1000*$Q$4/1000000000 -> 0.22499503 | J33: =J32+(J$38-J$28)/11 -> 1249972.4 | K33: =N33*$P$4/1000000 -> 17.385813 | L33: =J33/J32 -> 0.96888889 | M33: =N33*$P$4/1000000 -> 17.385813 | N33: =O32*L33 -> 915042.79 | O33: =O32+(O$154-O$4)/150 -> 937831.25
A34: =A33+1 -> 30 | B34: =B33+1 -> 2059 | C34: =(D34*G34+D33*F33)/F34 -> 11.479761 | D34: =(K34+I34)*1000/G34*1000 -> 11.692357 | E34: =F34/1000000 -> 70.340221 | F34: =F33+H33+J33 -> 70340221 | G34: =H34+J34 -> 1493659.6 | H34: =$P$21 -> 283824 | I34: =J34*1000*$Q$4/1000000000 -> 0.21777041 | J34: =J33+(J$38-J$28)/11 -> 1209835.6 | K34: =N34*$P$4/1000000 -> 17.246631 | L34: =J34/J33 -> 0.96788991 | M34: =N34*$P$4/1000000 -> 17.246631 | N34: =O33*L34 -> 907717.4 | O34: =O33+(O$154-O$4)/150 -> 931237.6
A35: =A34+1 -> 31 | B35: =B34+1 -> 2060 | C35: =(D35*G35+D34*F34)/F35 -> 11.690306 | D35: =(K35+I35)*1000/G35*1000 -> 11.913862 | E35: =F35/1000000 -> 71.833881 | F35: =F34+H34+J34 -> 71833881 | G35: =H35+J35 -> 1453522.9 | H35: =$P$21 -> 283824 | I35: =J35*1000*$Q$4/1000000000 -> 0.2105458 | J35: =J34+(J$38-J$28)/11 -> 1169698.9 | K35: =N35*$P$4/1000000 -> 17.106526 | L35: =J35/J34 -> 0.96682464 | M35: =N35*$P$4/1000000 -> 17.106526 | N35: =O34*L35 -> 900343.46 | O35: =O34+(O$154-O$4)/150 -> 924643.95
A36: =A35+1 -> 32 | B36: =B35+1 -> 2061 | C36: =(D36*G36+D35*F35)/F36 -> 11.911838 | D36: =(K36+I36)*1000/G36*1000 -> 12.147228 | E36: =F36/1000000 -> 73.287404 | F36: =F35+H35+J35 -> 73287404 | G36: =H36+J36 -> 1413386.2 | H36: =$P$21 -> 283824 | I36: =J36*1000*$Q$4/1000000000 -> 0.20332119 | J36: =J35+(J$38-J$28)/11 -> 1129562.2 | K36: =N36*$P$4/1000000 -> 16.965404 | L36: =J36/J35 -> 0.96568627 | M36: =N36*$P$4/1000000 -> 16.965404 | N36: =O35*L36 -> 892915.97 | O36: =O35+(O$154-O$4)/150 -> 918050.31
A37: =A36+1 -> 33 | B37: =B36+1 -> 2062 | C37: =(D37*G37+D36*F36)/F37 -> 12.145227 | D37: =(K37+I37)*1000/G37*1000 -> 12.393416 | E37: =F37/1000000 -> 74.70079 | F37: =F36+H36+J36 -> 74700790 | G37: =H37+J37 -> 1373249.5 | H37: =$P$21 -> 283824 | I37: =J37*1000*$Q$4/1000000000 -> 0.19609658 | J37: =J36+(J$38-J$28)/11 -> 1089425.5 | K37: =N37*$P$4/1000000 -> 16.823155 | L37: =J37/J36 -> 0.96446701 | M37: =N37*$P$4/1000000 -> 16.823155 | N37: =O36*L37 -> 885429.23 | O37: =O36+(O$154-O$4)/150 -> 911456.66
A38: =A37+1 -> 34 | B38: =B37+1 -> 2063 | C38: =(D38*G38+D37*F37)/F38 -> 12.382953 | D38: =(K38+I38)*1000/G38*1000 -> 12.547243 | E38: =F38/1000000 -> 76.074039 | F38: =F37+H37+J37 -> 76074039 | G38: =H38+J38 -> 1292976 | H38: =$P$21 -> 283824 | I38: =J38*1000*$Q$4/1000000000 -> 0.18164736 | J38: 1009152 | K38: =N38*$P$4/1000000 -> 16.041637 | L38: =J38/J37 -> 0.92631579 | M38: =N38*$P$4/1000000 -> 16.041637 | N38: =O37*L38 -> 844296.7 | O38: =O37+(O$154-O$4)/150 -> 904863.01
A39: =A38+1 -> 35 | B39: =B38+1 -> 2064 | C39: =(D39*G39+D38*F38)/F39 -> 12.554374 | D39: =(K39+I39)*1000/G39*1000 -> 13.332727 | E39: =F39/1000000 -> 77.367015 | F39: =F38+H38+J38 -> 77367015 | G39: =H39+J39 -> 1258177.7 | H39: =$P$21 -> 283824 | I39: =J39*1000*$Q$4/1000000000 -> 0.17538366 | J39: =J38+(J$67-J$38)/29 -> 974353.66 | K39: =N39*$P$4/1000000 -> 16.599556 | L39: =J39/J38 -> 0.96551724 | M39: =N39*$P$4/1000000 -> 16.599556 | N39: =O38*L39 -> 873660.84 | O39: =O38+(O$154-O$4)/150 -> 898269.37
A40: =A39+1 -> 36 | B40: =B39+1 -> 2065 | C40: =(D40*G40+D39*F39)/F40 -> 13.330842 | D40: =(K40+I40)*1000/G40*1000 -> 13.590795 | E40: =F40/1000000 -> 78.625193 | F40: =F39+H39+J39 -> 78625193 | G40: =H40+J40 -> 1223379.3 | H40: =$P$21 -> 283824 | I40: =J40*1000*$Q$4/1000000000 -> 0.16911996 | J40: =J39+(J$67-J$38)/29 -> 939555.31 | K40: =N40*$P$4/1000000 -> 16.457578 | L40: =J40/J39 -> 0.96428571 | M40: =N40*$P$4/1000000 -> 16.457578 | N40: =O39*L40 -> 866188.32 | O40: =O39+(O$154-O$4)/150 -> 891675.72
...

Sheet Nitrogen
C1: Vinter | D1: sommer | E1: Total/år | G1: KOMMENTAR
A2: Övergripande | B2: Förbrukad mgd sprängmedel [ton/år] | C2: =E2*5/12 -> 2982.0833 | D2: =E2-C2 -> 4174.9167 | E2: 7157 | G2: Data från TB 2012-07-06, basert på 15.5 Mton/år malm och 11 Mton/år sidoberg. Vinterperiode med frost, uten avrenning satt til 5 mnd/år
B3: Kvävekvot i sprängmedel [%] | C3: 0.27 | D3: =C3 -> 0.27 | E3: =D3 -> 0.27
B4: Spillkvot [%] | C4: 0.02 | D4: =C4 -> 0.02 | E4: =D4 -> 0.02
B5: Spillt kväve inn i systemet [kg/år] | C5: =C2*C3*C4*1000 -> 16103.25 | D5: =D2*D3*D4*1000 -> 22544.55 | E5: =E2*E3*E4*1000 -> 38647.8
B6: Malm (Mton/år) | C6: =E6*5/12 -> 6.4583333 | D6: =E6-C6 -> 9.0416667 | E6: 15.5
B7: Sidoberg (Mton/år) | C7: =E7*5/12 -> 4.5833333 | D7: =E7-C7 -> 6.4166667 | E7: 11
A9: Delflöden | B9: Till länshållningsvatten [%] | C9: 0 | D9: =0.3333 -> 0.3333 | E9: =(C9+D9)/2 -> 0.16665 | G9: Antar at det brukes like my sprengemne for sidoberg som malm. Fordeling sidoberg-malm gir sprengmeldel rest til fordeling. Antar at all sprengmedel går til sideberg opplåg och malmprocesseringen.
B10: Till sidoberg [%] | C10: =C7/(C6+C7)/100% -> 0.41509434 | D10: =D7/(D6+D7)/100%*0.6667 -> 0.2767434 | E10: =(C10+D10)/2 -> 0.34591887 | F10: kontrollsumma
B11: Till malm [%] | C11: =C6/(C6+C7)/100% -> 0.58490566 | D11: =D6/(D6+D7)/100%*0.6667 -> 0.3899566 | E11: =(C11+D11)/2 -> 0.48743113 | F11: =SUM(D9:D11) -> 1
A13: Malm | B13: malm -->sovringsavfall [%] | C13: 0.09 | D13: =C13 -> 0.09 | F13: kontrollsumma
B14: malm-->anrikningsrågods [%] | C14: 0.16 | D14: =C14 -> 0.16 | F14: =SUM(C13:C14)+C17+C18 -> 1
B15: Urtvättning av kväve från upplag anrikningsrågods [% - av med materialet upplagt N-tot] | C15: 0 | D15: 0.05 | G15: Upplag anrikningsrågods ca en vecka i genomsnitt (plats finns för detta). Upplag för malm bara i genomsnitt max en dag (försummas därför).
B16: Urtvättning av kväve från upplag malm/anrikningsrågods [% - av N-tot] -->sedimentationsdamm via uppsamlingsdike | C16: =C15*C14 -> 0 | D16: =D15*D14 -> 0.008
B17: Processvatten | C17: =1-C13-C14-C18 -> 0.59 | D17: =1-D13-D14-D18 -> 0.598
B18: N-tot med anrikningsrågods ut ur systemet [%] | C18: =C14-C16 -> 0.16 | D18: =D14-D16 -> 0.152
B19: N-tot ut till sed.damm [kg/år] | C19: =C16*C5*C11+C11*C17*C5 -> 5557.1404 | D19: =D16*D5*D11+D11*D17*D5 -> 5327.5861 | G19: Anrikningsavfall och processvatten går ochså til sedimentasjonsdamm
B20: NH4-N [kg/år] ut till sed.damm | C20: =C19/2 -> 2778.5702 | D20: =D19/2 -> 2663.793
A23: Från upplag sovringsavfall till sedimentationsdamm | B23: N-tot in till upplag sovringsavfall [kg/år] | C23: =C13*C5 -> 1449.2925 | D23: =D13*D5 -> 2029.0095
B24: 2a. Andel totalkväve som blir kvar på lång sikt i upplaget [%] | C24: 0 | D24: =C24 -> 0
B25: 2b. Andel av lakvatten som transporteras diffust under dike och vidare (gv-bildning till berg samt grundvatten i jord under dikesbotten). [%] | C25: 0 | D25: 0.2 | G25: Mertainen info (Bergab)
B26: 2c. Andel NH4-N av N-tot ut till uppsamlingsdike vid upplagsfot. [%] | C26: 0 | D26: 0.1 | G26: Mertainen info (Bergab)
B27: Från upplag sovringsavfall till sedimentationsdamm N-tot [kg /år] | C27: 0 | D27: =(D23+C23)*(1-D24)*(1-D25) -> 2782.6416
B28: NH4-N [kg/år] ut till sed.damm | C28: =C26*C27 -> 0 | D28: =D26*D27 -> 278.26416
A31: Från upplag sidoberg till sedimentationsdamm | B31: N-tot in till upplag sidoberg [kg/år] | C31: =C10*C5 -> 6684.3679 | D31: =D10*D5 -> 6239.0553
B32: 3a. Andel totalkväve som blir kvar på lång sikt i upplaget [%] | C32: 0 | D32: =C32 -> 0
B33: 3b. Andel av lakvatten som transporteras diffust under dike och vidare (gv-bildning till berg samt grundvatten i jord under dikesbotten). [%] | C33: 0 | D33: 0.2
B34: 3c. Andel NH4-N av N-tot ut till uppsamlingsdike vid upplagsfot. [%] | C34: 0 | D34: =0.1 -> 0.1
B35: Från upplag sidoberg till sedimentationsdamm N-tot [kg /år] | C35: 0 | D35: =(D31+C31)*(1-D32)*(1-D33) -> 10338.739
B36: NH4-N [kg/år] ut till sed.damm | C36: =C35*C34 -> 0 | D36: =D35*D34 -> 1033.8739
A38: Länshållningsvattenfrån dagbrott | B38: N-tot in till länshållningsvatten [kg/år] | C38: =C5*C9 -> 0 | D38: =D5*D9 -> 7514.0985
B39: Andel NH4-N av N-tot länshållningsvatten. [%] | C39: 0.15 | D39: 0.25 | G39: Mertainen info (Bergab)
B40: N-tot lensholdningsvatten [kg/år] | C40: =C38 -> 0 | D40: =D38 -> 7514.0985
B41: NH4-N [kg/år] Lensholdningsvatten | C41: =C38*C39 -> 0 | D41: =D38*D39 -> 1878.5246
